Workbook
Name __a1: #REF!
Name __a1: #REF!
Name __rec32: #REF!
Name __rec32: #REF!
Name __rec37: #REF!
Name __rec37: #REF!
Name __rec52: #REF!
Name __rec52: #REF!
Name __rec53: #REF!
Name __rec53: #REF!
Name __rec60: #REF!
Name __rec60: #REF!
Name __rec86: #REF!
Name __rec86: #REF!
Name _1__Negligible: #REF!
Name _1__Negligible: #REF!
Name _a1: #REF!
Name _a1: #REF!
Name _a2: #REF!
Name _a2: #REF!
Name _rec32: #REF!
Name _rec32: #REF!
Name _rec33: #REF!
Name _rec33: #REF!
Name _rec37: #REF!
Name _rec37: #REF!
Name _rec52: #REF!
Name _rec52: #REF!
Name _rec53: #REF!
Name _rec53: #REF!
Name _rec60: #REF!
Name _rec60: #REF!
Name _rec86: #REF!
Name _rec86: #REF!
Name a: #REF!
Name a: #REF!
Name aa: #REF!
Name aa: #REF!
Name Access.Control.System.Malfunction.OR.Failure: [1]VulRepo!#REF!
Name Access.Control.System.Malfunction.OR.Failure: [1]VulRepo!#REF!
Name Access.Control.System.Malfunction.OR.Failure: [1]VulRepo!#REF!
Name Acoustic.Shocks: [1]VulRepo!#REF!
Name Acoustic.Shocks: [1]VulRepo!#REF!
Name Acoustic.Shocks: [1]VulRepo!#REF!
Name Actuarial: #REF!
Name Actuarial: #REF!
Name Actuarial: #REF!
Name Actuarial_Hard_Copy_Business_Confidential: #REF!
Name Actuarial_Hard_Copy_Business_Confidential: #REF!
Name Actuarial_Hard_Copy_Business_Confidential: #REF!
Name Actuarial_People_Business_Private: #REF!
Name Actuarial_People_Business_Private: #REF!
Name Actuarial_People_Business_Private: #REF!
Name Actuarial_People_Public: #REF!
Name Actuarial_People_Public: #REF!
Name Actuarial_People_Public: #REF!
Name Actuarial_Soft_Copy_Business_Confidential: #REF!
Name Actuarial_Soft_Copy_Business_Confidential: #REF!
Name Actuarial_Soft_Copy_Business_Confidential: #REF!
Name Actuarial_Software_Business_Secret: #REF!

Sheet Template Information
B2: Risk Assessment Form
B3: Business / Support
B4: Project Name / Support Group:
B5: Project / Support Code
B6: Delivery Location(s)
B7: Scope of Risk Assessment
B8: Prepared by
B9: Reviewed by (Engagement Manager)
B10: Risk Owner's Employee ID
B11: Approved by (Risk Owner)
B12: Declaration: I <<Enter Name of Risk Owner>, <<Enter Employee ID>>, hereby, approve the information security risk treatment plan and accept the residual information security risks
B13: Risk Treatment Plan Status | E13: Draft
B14: Last updated
B15: Next Review date
B17: Version Number | C17: Date of Approval | D17: Reviewed By | E17: Approved By | F17: Change Description
B18: 0.1
B19: 0.2
B20: 1
B21: 1.1
B22: 2

Sheet Asset Inventorization Guideline
A1: Guidelines for Asset Inventorization
A2: Asset Inventorization is done based on discussions with the asset class / business owner. Information pertaining to the asset including type of the asset, format, location, license information is captured in the Asset Inventory (shown in the next spreadsheet) as required by ISO 27001. In addition a business value and a security classification is assigned to the asset and captured in the Asset Inventory. The various steps as a part of Asset Inventorization are as shown below:
A4: Guidelines for determining the Asset Business Value
A5: As a preliminary step the Business Impact on the organization due to the compromise of Confidentiality, Integrity, Availability (C, I, A) of the asset is captured individually and rated across four categories. (Insignificant, Moderate, Serious and Extreme). Business Impact on the organization may be Regulatory Impact, Financial Impact, Customer Service Impact, Health and Safety Impact, Operational Impact and Reputational Impact. The guidelines for determining the business impact ratings are as shown below:
A6: Business Impact Rating | B6: Loss of Confidentiality | C6: Loss of Integrity | D6: Loss of Availability
A7: Insignificant | B7: Disclosure within or outside the organization will not harm the interest of the organization but maybe considered inappropriate. | C7: Unauthorized modification or damage of information is expected to have a low adverse effect on business operations. | D7: Impact of disruption of access or unavailability of information or information asset or services is expected to have a low adverse effect on business operations.
A8: Moderate | B8: Unauthorized disclosure within or outside the organization may harm the interest of the organization. | C8: Unauthorized modification or damage of information is expected to have a moderate adverse effect on business operations. | D8: Impact of disruption of access or unavailability of information or information asset or services is expected to have a moderate adverse effect on business operations.
A9: Serious | B9: Unauthorized disclosure within or outside the organization would cause significant harm to the interest of the organization. | C9: Unauthorized modification or damage of information is expected to have a serious adverse effect on business operations. | D9: Impact of disruption of access or unavailability of information or information asset or services is expected to have a serious adverse effect on business operations.
A10: Extreme | B10: Unauthorized disclosure within or outside the organization would cause serious damage to the interests of the organization. Disclosure within the organization will be strictly on a ‘need-to-know’ basis. | C10: Unauthorized modification or damage of information is expected to have severe and long ranging adverse effect on business operations. | D10: Impact of disruption of access or unavailability of information or information asset or services is expected to have severe and long ranging adverse effect on business operations.
A11: Once the Business Impact Ratings for the compromise of the C, I and A of the asset are determined then the overall Asset Business Value is determined by the Asset Value Chart as shown below:
A12: Asset Value | B12: Confidentiality | C12: Insignificant | G12: Moderate | K12: Serious | O12: Extreme
A13: Matrix | B13: Availability | C13: Insignificant | D13: Moderate | F13: Extreme | G13: Insignificant | H13: Moderate | J13: Extreme | K13: Insignificant | L13: Moderate | N13: Extreme | O13: Insignificant | P13: Moderate | R13: Extreme
E14: Serious | I14: Serious | M14: Serious | Q14: Serious
A15: Integrity | B15: Insignificant | C15: Very low | D15: Very low | E15: Medium | F15: High | G15: Very low | H15: Low | I15: Medium | J15: High | K15: Medium | L15: Medium | M15: High | N15: High | O15: High | P15: High | Q15: High | R15: Very High
A16: Value | B16: Moderate | C16: Very low | D16: Low | E16: Medium | F16: High | G16: Low | H16: Low | I16: Medium | J16: High | K16: Medium | L16: Medium | M16: High | N16: High | O16: High | P16: High | Q16: High | R16: Very High
B17: Serious | C17: Medium | D17: Medium | E17: High | F17: High | G17: Medium | H17: Medium | I17: High | J17: High | K17: High | L17: HIgh | M17: High | N17: High | O17: High | P17: High | Q17: High | R17: Very high
B18: Extreme | C18: High | D18: High | E18: High | F18: Very High | G18: High | H18: High | I18: High | J18: Very High | K18: High | L18: High | M18: High | N18: Very High | O18: Very High | P18: Very High | Q18: Very high | R18: Very high
A19: For example: If the Ratings for a particular asset have been determined as: Confidentiality-Low, Availability-Low, Integrity-Serious, then the Asset Business Value is "Low" as indicated in cell C16.
A20: Asset Business Value | B20: Definition | C20: Color
A21: Very Low | B21: Very low impact on business if C,I and A of asset gets compromised
A22: Low | B22: Low impact on business if C,I and A of asset gets compromised
A23: Medium | B23: Medium impact on business if C,I and A of asset gets compromised
A24: High | B24: High impact on business if C,I and A of asset gets compromised
A25: Very High | B25: Very high impact on business if C,I and A of asset gets compromised
A26: Guidelines for determining the Asset Security Classification
A27: Based on the Asset Business Value, classify the assets for criticality as per the following table:
A28: Asset Business Value | B28: Asset Criticality Classification | C28: Description
A29: Very Low | B29: Insignificant | C29: Very low impact on business if C,I and A of asset gets compromised
A30: Low | B30: Low Critical | C30: Low impact on business if C,I and A of asset gets compromised
A31: Medium | B31: Medium Critical | C31: Medium impact on business if C,I and A of asset gets compromised
A32: High | B32: High Critical | C32: High impact on business if C,I and A of asset gets compromised
A33: Very high | B33: Very high Critical | C33: Very high impact on business if C,I and A of asset gets compromised

Sheet Asset Inventory
A1: Asset Inventory | F1: Function_Name
A2: The asset inventory is populated function wise based on discussions with the asset class / function owner. After capturing preliminary information regarding the asset, the Business Impact Ratings due to the compromise of the C, I & A of the asset are captured as per the Asset Valuation Guidelines, previously mentioned, and the overall Business Value of the asset is automatically derived by the tool kit. (as per the Asset Value Chart previously mentioned)
A5: Sno. | B5: Asset Information | F5: Asset Valuation | J5: Asset Classification
B6: Asset Class Name (Title / Description of Asset) | C6: Type of Asset | D6: Asset Class Owner | E6: Location | F6: Business Impact - due to loss of Confidentiality | G6: Business Impact - due to loss of Integrity | H6: Business Impact - due to loss of Availability | I6: Asset business value | J6: Asset Criticality Classification
A7: 1 | B7: Asset Class Name1 Description:- Examples:- | I7: =VLOOKUP(F7&G7&H7, $Y$139:$Z$202, 2, 0) -> #N/A | J7: =VLOOKUP(I7, 'Asset Inventorization Guideline'!$A$29:$B$33, 2, 0) -> #N/A
A8: 2 | B8: Asset Class Name2 Description:- Examples:- | I8: =VLOOKUP(F8&G8&H8, $Y$139:$Z$202, 2, 0) -> #N/A | J8: =VLOOKUP(I8, 'Asset Inventorization Guideline'!$A$29:$B$33, 2, 0) -> #N/A
A9: 3 | B9: Asset Class Name3 Description:- Examples:- | I9: =VLOOKUP(F9&G9&H9, $Y$139:$Z$202, 2, 0) -> #N/A | J9: =VLOOKUP(I9, 'Asset Inventorization Guideline'!$A$29:$B$33, 2, 0) -> #N/A
A10: 4 | B10: Asset Class Name4 Description:- Examples:- | I10: =VLOOKUP(F10&G10&H10, $Y$139:$Z$202, 2, 0) -> #N/A | J10: =VLOOKUP(I10, 'Asset Inventorization Guideline'!$A$29:$B$33, 2, 0) -> #N/A
A11: 5 | B11: Asset Class Name5 Description:- Examples:- | I11: =VLOOKUP(F11&G11&H11, $Y$139:$Z$202, 2, 0) -> #N/A | J11: =VLOOKUP(I11, 'Asset Inventorization Guideline'!$A$29:$B$33, 2, 0) -> #N/A
A12: 6 | B12: Asset Class Name6 Description:- Examples:- | I12: =VLOOKUP(F12&G12&H12, $Y$139:$Z$202, 2, 0) -> #N/A | J12: =VLOOKUP(I12, 'Asset Inventorization Guideline'!$A$29:$B$33, 2, 0) -> #N/A
A13: 7 | B13: Asset Class Name7 Description:- Examples:- | I13: =VLOOKUP(F13&G13&H13, $Y$139:$Z$202, 2, 0) -> #N/A | J13: =VLOOKUP(I13, 'Asset Inventorization Guideline'!$A$29:$B$33, 2, 0) -> #N/A
V138: c | W138: i | X138: a
V139: Insignificant | W139: Insignificant | X139: Insignificant | Y139: =V139&W139&X139 -> InsignificantInsignificantInsignificant | Z139: Very Low | AA139: Insignificant
V140: Insignificant | W140: Insignificant | X140: Moderate | Y140: =V140&W140&X140 -> InsignificantInsignificantModerate | Z140: Very Low | AA140: Insignificant
V141: Insignificant | W141: Moderate | X141: Insignificant | Y141: =V141&W141&X141 -> InsignificantModerateInsignificant | Z141: Very Low | AA141: Insignificant
V142: Moderate | W142: Insignificant | X142: Insignificant | Y142: =V142&W142&X142 -> ModerateInsignificantInsignificant | Z142: Very Low | AA142: Insignificant
V143: Insignificant | W143: Moderate | X143: Moderate | Y143: =V143&W143&X143 -> InsignificantModerateModerate | Z143: Low | AA143: Low Critical
V144: Moderate | W144: Insignificant | X144: Moderate | Y144: =V144&W144&X144 -> ModerateInsignificantModerate | Z144: Low | AA144: Low Critical
V145: Moderate | W145: Moderate | X145: Insignificant | Y145: =V145&W145&X145 -> ModerateModerateInsignificant | Z145: Low | AA145: Low Critical
V146: Insignificant | W146: Insignificant | X146: Serious | Y146: =V146&W146&X146 -> InsignificantInsignificantSerious | Z146: Medium | AA146: Medium Critical
V147: Insignificant | W147: Serious | X147: Insignificant | Y147: =V147&W147&X147 -> InsignificantSeriousInsignificant | Z147: Medium | AA147: Medium Critical
V148: Serious | W148: Insignificant | X148: Insignificant | Y148: =V148&W148&X148 -> SeriousInsignificantInsignificant | Z148: Medium | AA148: Medium Critical
V149: Moderate | W149: Moderate | X149: Moderate | Y149: =V149&W149&X149 -> ModerateModerateModerate | Z149: Low | AA149: Low Critical
V150: Insignificant | W150: Moderate | X150: Serious | Y150: =V150&W150&X150 -> InsignificantModerateSerious | Z150: Medium | AA150: Medium Critical
... V202: Extreme | W202: Extreme | X202: Extreme | Y202: =V202&W202&X202 -> ExtremeExtremeExtreme | Z202: Very High | AA202: Very High Critical

Sheet RA Methodology
A2: Methodology
A3: Risk Assessment and Risk Treatment Plan
A4: Risk assessment and treatment plan Objective Identifications of risks to asset class for threats identified and determining the action plans against risks where existing controls are not effective. The Risk Treatment approach lists the threats and risk ratings arrived at, in the Risk Assessment exercise. Basis the risk evaluation rating, Risk treatment strategies is adopted to treat each of the identified threats. Methodology Post identification of the asset classes and asset business value , Risk Assessment shall be conducted. All identified asset classes shall be subject to applicable threat and vulnerabilities The following steps are to be executed while conducting risk assessment scale shall be used
A5: Impact
A6: Impact shall be quantified as a numerical quantity to reflect damage if a given threat successfully exploits a given vulnerability. Impact is not related to probability. This value allows us to rate on a relative scale the seriousness of a given risk independent of its probability.
A7: For this Risk Assessment the following scale shall be used to estimate impact:
A8: Impact Category | B8: Impact Definition | C8: Impact Rating
A9: Very Low | B9: Risk has negligible impact on business and operations | C9: 1
A10: Low | B10: Risk does not have significant impact on business and operations | C10: 2
A11: Medium | B11: Risk has minimum impact on business and operations | C11: 3
A12: High | B12: Risk has serious impact on business and operations | C12: 4
A13: Very High | B13: Risk has catastrophic impact on business and operations | C13: 5
A14: Probability
A15: Probability is the likelihood of occurrence of a threat exploiting an identified vulnerability on an asset .Probability of the threat or failure should be captured after considering the vulnerabilities identified. For the purposes of this Risk Assessment the following scale shall be used to quantify probability.
A16: Probability Category | B16: Probability Definition | C16: Probability Rating
A17: Very Low | B17: Greater than one year | C17: 1
A18: Low | B18: Once every year | C18: 2
A19: Medium | B19: Moderate / Medium: once every 4-6 months | C19: 3
A20: High | B20: Major / High: once every 1-3 months | C20: 4
A21: Very High | B21: Severe / Very high: more than once per month | C21: 5
A22: Formula 1: Risk Value: Risk value is calculated basis the below given formula: Risk value = (Risk Impact*Risk Probability) Formual 2: Risk Evaluation Rating Risk evaluation rating is bucketing of Risk value as perthe mentioned:
A23: Risk Rating | B23: Risk value score | C23: Risk Rating
A24: 1 | B24: 0 to 5
A25: 2 | B25: 6 to 10
A26: 3 | B26: 11 to 15
A27: 4 | B27: 16 to 20
A28: 5 | B28: 21 to 25
A29: 3: Post identification of risk rating, current controls shall be identified basis preventive, detective and corrective controls which are already in place, to minimize the impact of the respective risks due to the underlying vulnerabilities and threats. The controls are rated on a scale of 1 to 5, basis the following rating definitions defined in the template.
A30: Preventive/Detective/Corrective Control Rating | B30: Definition
A31: 1 | B31: Non-existent or has major deficiencies and do not operate as intended.
A32: 2 | B32: Limited, high level of risk remains, significant deficiencies.
A33: 3 | B33: Controls in place with few deficiencies in terms of medium risk issues.
A34: 4 | B34: Designed and operating, with few deficiencies in terms of low risk issues.
A35: 5 | B35: Designed and operating, with no deficiencies.
A36: The current controls rating is taken from the value of Preventive, Detective, and Corrective. Weightage of preventive control is taken as 1, weightage of detective control is taken as 0.75 and weightage of Corrective controls is taken as 0.5; in order to proactively reduce the probability and impact of the threat to materialize. Formula#3: (Current Control Rating) = FLOOR (AVERAGE(Preventive Control Rating *1,Detective Control Rating *0.75, Corrective Control Rating*0.5) 4: The difference between risk rating and current control rating shall be considered to determine residual risk basis which Management Decision shall be triggered Formula#4 (Calculation of Residual Risk): Risk Rating – Control Rating Residual Risk value shall be either 1, 2, 3, 4 or 5. Risk appetite is the amount and type of risk that organization can sustain with; without adversely affecting its business operations. In case of derived residual risk is less than or equal to ‘2’, the pertaining risks shall be a part of organizations as risk appetite. In cases where the residual risk is more than ‘2’, mitigation shall be required. The management shall review the risk description and direct the further actions basis the 4T methodology: • Treat: involves taking action to reduce the risk by lessening the impact. This can involve improved procedures or training, investing in new equipment, changing legislation, etc. • Accept: involves accepting the risk and its impact as it stands that is self-insure or decide to cover any losses. Risks we have failed to identify are classed as being tolerated without knowledge • Transfer: involves deciding to pass the risk or costs of the impact outside the organization, that is contract out the risk or take out insurance to cover the costs of the impact • Terminate: involves deciding to eliminate the risk by ceasing the activity on the pursuance of the objective that presents the risk

Sheet Risk Assessment
A1: Sno. | B1: Asset Class Name (Title / Description of Asset) | C1: Asset business Value | D1: Threat | E1: Associated Vulnerabilities | F1: Risk Statements | G1: Risk Impact | H1: Risk Probability | I1: Risk value | J1: Risk Evaluation Rating | K1: Management Decision | L1: Existing Control Type | U1: Residual Risk Rating | X1: Management Decision | Y1: Reason for Acceptance
L2: Preventive Controls (P) | M2: (P) Rating | N2: Average of Preventive Control Rating | O2: Detective Controls (D) | P2: (D) Rating | Q2: Average of Detective Control Rating | R2: Corrective Controls © | S2: © Rating | T2: Average of Corrective Control Rating | U2: Control Rating | V2: Risk Value | W2: Residual Risk Value
A3: 1 | B3: ='Asset Inventory'!B7 -> Asset Class Name1 Description:- Examples:- | C3: ='Asset Inventory'!I7 -> #N/A | I3: =G3*H3 -> 0 | J3: =VLOOKUP(I3,$AB$695:$AC$715,2,0) -> #N/A | K3: Treat | N3: =AVERAGE(M3:M9) -> #DIV/0! | Q3: =AVERAGE(P3:P9) -> #DIV/0! | T3: =AVERAGE(S3:S9) -> #DIV/0! | U3: =FLOOR(AVERAGE(N3*1,Q3*0.75,T3*0.5),1) -> #DIV/0! | V3: =J3 -> #N/A | W3: =V3-U3 -> #N/A | X3: Accept | Y3: NA
I4: =G4*H4 -> 0 | J4: =VLOOKUP(I4,$AB$695:$AC$715,2,0) -> #N/A
I5: =G5*H5 -> 0 | J5: =VLOOKUP(I5,$AB$695:$AC$715,2,0) -> #N/A
I6: =G6*H6 -> 0 | J6: =VLOOKUP(I6,$AB$695:$AC$715,2,0) -> #N/A
I7: =G7*H7 -> 0 | J7: =VLOOKUP(I7,$AB$695:$AC$715,2,0) -> #N/A
I8: =G8*H8 -> 0 | J8: =VLOOKUP(I8,$AB$695:$AC$715,2,0) -> #N/A
I9: =G9*H9 -> 0 | J9: =VLOOKUP(I9,$AB$695:$AC$715,2,0) -> #N/A
A10: 2 | B10: ='Asset Inventory'!B8 -> Asset Class Name2 Description:- Examples:- | C10: ='Asset Inventory'!I8 -> #N/A | I10: =G10*H10 -> 0 | J10: =VLOOKUP(I10,$AB$695:$AC$715,2,0) -> #N/A | K10: Accept | L10: NA | M10: NA | N10: NA | O10: NA | P10: NA | Q10: NA | R10: NA | S10: NA | T10: NA | U10: NA | V10: NA | W10: Na | X10: NA | Y10: <reason for acceptance>
I11: =G11*H11 -> 0 | J11: =VLOOKUP(I11,$AB$695:$AC$715,2,0) -> #N/A
I12: =G12*H12 -> 0 | J12: =VLOOKUP(I12,$AB$695:$AC$715,2,0) -> #N/A
I13: =G13*H13 -> 0 | J13: =VLOOKUP(I13,$AB$695:$AC$715,2,0) -> #N/A
I14: =G14*H14 -> 0 | J14: =VLOOKUP(I14,$AB$695:$AC$715,2,0) -> #N/A
I15: =G15*H15 -> 0 | J15: =VLOOKUP(I15,$AB$695:$AC$715,2,0) -> #N/A
I16: =G16*H16 -> 0 | J16: =VLOOKUP(I16,$AB$695:$AC$715,2,0) -> #N/A
A17: 3 | B17: ='Asset Inventory'!B9 -> Asset Class Name3 Description:- Examples:- | C17: ='Asset Inventory'!I9 -> #N/A | I17: =G17*H17 -> 0 | J17: =VLOOKUP(I17,$AB$695:$AC$715,2,0) -> #N/A | K17: Treat | N17: =AVERAGE(M17,M18,M19) -> #DIV/0! | Q17: =AVERAGE(P17,P18,P19) -> #DIV/0! | T17: =AVERAGE(S17,S18,S19) -> #DIV/0! | U17: =FLOOR(AVERAGE(N17*1,Q17*0.75,T17*0.5),1) -> #DIV/0! | V17: =J17 -> #N/A | W17: =V17-U17 -> #N/A | X17: Accept | Y17: NA
I18: =G18*H18 -> 0 | J18: =VLOOKUP(I18,$AB$695:$AC$715,2,0) -> #N/A
I19: =G19*H19 -> 0 | J19: =VLOOKUP(I19,$AB$695:$AC$715,2,0) -> #N/A
I20: =G20*H20 -> 0 | J20: =VLOOKUP(I20,$AB$695:$AC$715,2,0) -> #N/A | K20: Accept | L20: NA | M20: NA | N20: NA | O20: NA | P20: NA | Q20: NA | R20: NA | S20: NA | T20: NA | U20: NA | V20: NA | W20: NA | X20: NA | Y20: <reason for acceptance>
I21: =G21*H21 -> 0 | J21: =VLOOKUP(I21,$AB$695:$AC$715,2,0) -> #N/A | K21: Accept | L21: NA | M21: NA | N21: NA | O21: NA | P21: NA | Q21: NA | R21: NA | S21: NA | T21: NA | U21: NA | V21: NA | W21: NA | X21: NA | Y21: <reason for acceptance>
I22: =G22*H22 -> 0 | J22: =VLOOKUP(I22,$AB$695:$AC$715,2,0) -> #N/A | K22: Treat | N22: =AVERAGE(M22,M23,M24) -> #DIV/0! | Q22: =AVERAGE(P22,P23,P24) -> #DIV/0! | T22: =AVERAGE(S22,S23,S24) -> #DIV/0! | U22: =FLOOR(AVERAGE(N22*1,Q22*0.75,T22*0.5),1) -> #DIV/0! | V22: =J22 -> #N/A | W22: =V22-U22 -> #N/A | X22: Accept | Y22: NA
I23: =G23*H23 -> 0 | J23: =VLOOKUP(I23,$AB$695:$AC$715,2,0) -> #N/A
I24: =G24*H24 -> 0 | J24: =VLOOKUP(I24,$AB$695:$AC$715,2,0) -> #N/A
A25: 4 | B25: ='Asset Inventory'!B10 -> Asset Class Name4 Description:- Examples:- | C25: ='Asset Inventory'!I10 -> #N/A | I25: =G25*H25 -> 0 | J25: =VLOOKUP(I25,$AB$695:$AC$715,2,0) -> #N/A | K25: Treat | N25: =AVERAGE(M25,M26,M27) -> #DIV/0! | Q25: =AVERAGE(P25,P26,P27) -> #DIV/0! | T25: =AVERAGE(S25,S26,S27) -> #DIV/0! | U25: =FLOOR(AVERAGE(N25*1,Q25*0.75,T25*0.5),1) -> #DIV/0! | V25: =J25 -> #N/A | W25: =V25-U25 -> #N/A | X25: Accept | Y25: NA
I26: =G26*H26 -> 0 | J26: =VLOOKUP(I26,$AB$695:$AC$715,2,0) -> #N/A
I27: =G27*H27 -> 0 | J27: =VLOOKUP(I27,$AB$695:$AC$715,2,0) -> #N/A
I28: =G28*H28 -> 0 | J28: =VLOOKUP(I28,$AB$695:$AC$715,2,0) -> #N/A | K28: Accept | L28: NA | M28: NA | N28: NA | O28: NA | P28: NA | Q28: NA | R28: NA | S28: NA | T28: NA | U28: NA | V28: NA | W28: NA | X28: NA | Y28: <reason for acceptance>
I29: =G29*H29 -> 0 | J29: =VLOOKUP(I29,$AB$695:$AC$715,2,0) -> #N/A | K29: Accept | L29: NA | M29: NA | N29: NA | O29: NA | P29: NA | Q29: NA | R29: NA | S29: NA | T29: NA | U29: NA | V29: NA | W29: NA | X29: NA | Y29: <reason for acceptance>
I30: =G30*H30 -> 0 | J30: =VLOOKUP(I30,$AB$695:$AC$715,2,0) -> #N/A | K30: Treat | N30: =AVERAGE(M30,M31,M32) -> #DIV/0! | Q30: =AVERAGE(P30,P31,P32) -> #DIV/0! | T30: =AVERAGE(S30,S31,S32) -> #DIV/0! | U30: =FLOOR(AVERAGE(N30*1,Q30*0.75,T30*0.5),1) -> #DIV/0! | V30: =J30 -> #N/A | W30: =V30-U30 -> #N/A | X30: Accept | Y30: NA
I31: =G31*H31 -> 0 | J31: =VLOOKUP(I31,$AB$695:$AC$715,2,0) -> #N/A
I32: =G32*H32 -> 0 | J32: =VLOOKUP(I32,$AB$695:$AC$715,2,0) -> #N/A
A33: 5 | B33: ='Asset Inventory'!B11 -> Asset Class Name5 Description:- Examples:- | C33: ='Asset Inventory'!I11 -> #N/A | I33: =G33*H33 -> 0 | J33: =VLOOKUP(I33,$AB$695:$AC$715,2,0) -> #N/A | K33: Treat | N33: =AVERAGE(M33,M34,M35) -> #DIV/0! | Q33: =AVERAGE(P33,P34,P35) -> #DIV/0! | T33: =AVERAGE(S33,S34,S35) -> #DIV/0! | U33: =FLOOR(AVERAGE(N33*1,Q33*0.75,T33*0.5),1) -> #DIV/0! | V33: =J33 -> #N/A | W33: =V33-U33 -> #N/A | X33: Accept | Y33: NA
I34: =G34*H34 -> 0 | J34: =VLOOKUP(I34,$AB$695:$AC$715,2,0) -> #N/A
I35: =G35*H35 -> 0 | J35: =VLOOKUP(I35,$AB$695:$AC$715,2,0) -> #N/A
I36: =G36*H36 -> 0 | J36: =VLOOKUP(I36,$AB$695:$AC$715,2,0) -> #N/A | K36: Accept | L36: NA | M36: NA | N36: NA | O36: NA | P36: NA | Q36: NA | R36: NA | S36: NA | T36: NA | U36: NA | V36: NA | W36: NA | X36: NA | Y36: <reason for acceptance>
I37: =G37*H37 -> 0 | J37: =VLOOKUP(I37,$AB$695:$AC$715,2,0) -> #N/A | K37: Accept | L37: NA | M37: NA | N37: NA | O37: NA | P37: NA | Q37: NA | R37: NA | S37: NA | T37: NA | U37: NA | V37: NA | W37: NA | X37: NA | Y37: <reason for acceptance>
I38: =G38*H38 -> 0 | J38: =VLOOKUP(I38,$AB$695:$AC$715,2,0) -> #N/A | K38: Treat | N38: =AVERAGE(M38,M39,M40) -> #DIV/0! | Q38: =AVERAGE(P38,P39,P40) -> #DIV/0! | T38: =AVERAGE(S38,S39,S40) -> #DIV/0! | U38: =FLOOR(AVERAGE(N38*1,Q38*0.75,T38*0.5),1) -> #DIV/0! | V38: =J38 -> #N/A | W38: =V38-U38 -> #N/A | X38: Accept | Y38: NA
I39: =G39*H39 -> 0 | J39: =VLOOKUP(I39,$AB$695:$AC$715,2,0) -> #N/A
I40: =G40*H40 -> 0 | J40: =VLOOKUP(I40,$AB$695:$AC$715,2,0) -> #N/A
...

Sheet Risk Treatment Plan
A1: Risk ID | B1: Risk Statement | C1: Risk Treatment Option | D1: Description of activities | E1: Necessary resources | F1: Implementation Priority | G1: Implementation Responsibility | H1: Proposed Deadline | J1: Actual Implementation Dates | L1: Risk Owner Comments | M1: Method for evaluation of results (If applicable) | N1: Status
H2: Start | I2: Completion | J2: Start | K2: Completion

Sheet Threat Vulnerability database
A1: Threats | B1: Associated Vulnerabilities
A2: Earthquake | B2: - Unavailability / Damage to critical information on paper -Lack of consideration towards siting of facility and avoidance of areas susceptible to seismic activity: Facility may locate in zone that falls under seismic zone 4. -Lack of adequate business continuity and disaster recovery plan. -Lack of adequate procedures to contact appropriate external authorities for remedial/recovery actions -Lack of preventive controls in place to mitigate risks from damage from earthquakes -Lack of adequate exercising and evacuation practices. - Lack of Site Risk Assessment.
A3: Flood | B3: - Lack of consideration towards siting of facility and avoidance of locations near water bodies - Inadequate procedures for coordination with public authorities - Lack of adequate business continuity and disaster recovery plan.
A4: Fire | B4: - Absence of fire detection and fire fighting equipment (such as fire extinguishers, sprinklers, fire and smoke detectors) - Presence of flammable materials within the facility: Office stationary such as cardboard, paper, etc. is stored within the premises; Unwanted flammable material is present in the server room. - Lack of fire drills/evacuation procedures, inspection of fire-fighting equipment. - Lack of consideration to siting and proximity to hazardous establishments (such as fuel depots, gas stations) - Inadequate coordination with public authorities (such as Police and Fire Dept.) - Lack of adequate business continuity and disaster recovery plan -Lack of monitoring procedures for temperature and humidity controls. -Lack of inspection / malfunctioning of fire-fighting, fire-supression, fire alerting and fire exits
A5: Storms/Wind/Lightning | B5: - Inadequate control measures such as Lack of Lightning arrestors and sensors - Inadequate coordination with public authorities (e.g. Police and Fire Dept.) - Lack of adequate business continuity and disaster recovery plan.
A6: Adverse Environmental Conditions | B6: - Lack of an environmental controls such as temperature and humidity Controls - Lack of adequate maintenance procedures (e.g. AMCs) - Lack of monitoring procedures
A7: Public Utilities Failure (Power/Water) | B7: - Lack of adequate backup measures for backup power supply - Inadequate monitoring procedures - Inadequate incident reporting procedures - Inadequate maintenance procedures (e.g. AMCs) - Lack of adequate business continuity plan
A8: Communications Failures (Telecom/ Internet/LAN) | B8: - Inadequate redundancy measures (such as standby equipment and alternate service providers) - Inadequate monitoring procedures - Lack of network management procedures - Lack of change control procedures - Inadequate incident reporting procedures - Inadequate access control - Lack of adequate business continuity plan
A9: Unintentional failure of IT systems (hardware/software) | B9: - Inadequate backup and restoration procedures - Lack of capacity management and performance monitoring procedures - Inadequate OS hardening - Inadequate version/configuration control procedures - Inadequate change/patch management procedures - Inadequate incident reporting procedures - Absence of periodic equipment maintenance - Lack of adequate business continuity plan - Lack of current and accessible documentation
A10: Electronic Sabotage and malicious code | B10: - Inadequate procedures on OS hardening - Absence of latest security patches - Inadequate Anti-virus definition updates - Inadequate information security awareness amongst users - Insufficient audit trails and lack of review of logs - Inadequate incident reporting procedures - Absence of definition and implementation of restrictions on usage of removable media - Inadequate user management procedures - Inadequate user privileges review - Lack of change control procedures - Inadequate network access restrictions - Inadequately protected security software/tools - Inadequate implementation of password controls
A11: Medical Emergencies | B11: - Lack of emergency health care on premises - Inadequate tie-ups with hospitals
A12: Unauthorized physical access/ Physical theft | B12: - Lack of restrictions on material movement - Lack of restrictions on physical entry and exit from the premises - Inadequate physical security policy - Inadequate physical monitoring of premises - Lack of adequate coordination with public authorities (e.g. Police Dept.) - Lack of awareness amongst users - Inadequate protection of material in transit - Facility is housed in a building that is shared with other companies.
... A20: Ineffective Third party governance | B20: - Partner monitoring not in place - Review meetings not conducted - Escalation Matrix not updated.

Sheet Risk & Threat Mapping
A1: S.no | B1: Threat | C1: Earthquake | D1: Flood | E1: Fire | F1: Storms/Wind/Lightning | G1: Adverse Environmental Conditions | H1: Public Utilities Failure (Power/Water) | I1: Communications Failures (Telecom/ Internet/LAN) | J1: Unintentional failure of IT systems (hardware/software) | K1: Electronic Sabotage and malicious code | L1: Medical Emergencies | M1: Unauthorized physical access/ Physical theft | N1: Loss of key personnel/ Attrition/ Poaching | O1: Negligent/Uninformed users | P1: Social Unrest (strikes, terrorist attacks, riots, etc.) | Q1: Inappropriate Information Disclosure | R1: Litigation Liabilities | S1: Fraud | T1: Lower Employee morale / Disgruntled Employee | U1: Ineffective Third party governance
B2: Risk Statement
A3: 1 | B3: Violation of legislation and/or regulation | K3: # | O3: # | Q3: # | S3: # | U3: #
A4: 2 | B4: Impairment of business performance | C4: # | D4: # | E4: # | F4: # | G4: # | H4: # | I4: # | J4: # | K4: # | M4: # | N4: # | O4: # | P4: # | R4: # | S4: # | T4: #
A5: 3 | B5: Loss of goodwill/negative effect on reputation | K5: # | M5: # | N5: # | O5: # | P5: # | Q5: # | R5: # | T5: #
A6: 4 | B6: Breach associated with personal information | K6: # | M6: # | N6: # | O6: # | Q6: # | S6: # | T6: #
A7: 5 | B7: Endangerment of personal safety | C7: # | D7: # | E7: # | F7: # | G7: # | L7: # | M7: # | P7: #
A8: 6 | B8: Adverse effects on law enforcement | M8: # | R8: #
A9: 7 | B9: Breach of confidentiality | K9: # | M9: # | N9: # | O9: # | P9: # | Q9: # | S9: # | T9: #
A10: 8 | B10: Financial loss | C10: # | D10: # | E10: # | F10: # | G10: # | H10: # | I10: # | J10: # | K10: # | M10: # | O10: # | P10: # | Q10: # | R10: # | S10: # | T10: #
A11: 9 | B11: Disruption to business activities | C11: # | D11: # | E11: # | F11: # | G11: # | H11: # | I11: # | J11: # | K11: # | L11: # | M11: # | N11: # | P11: # | R11: # | T11: #
A12: 10 | B12: Endangerment of environmental safety | C12: # | D12: # | E12: # | F12: # | G12: # | L12: # | P12: #
A13: 11 | B13: Interruption of service | C13: # | D13: # | E13: # | F13: # | G13: # | H13: # | I13: # | J13: # | K13: # | M13: # | P13: # | R13: #
A14: 12 | B14: Inability to provide the service | C14: # | D14: # | E14: # | F14: # | G14: # | H14: # | I14: # | J14: # | K14: # | P14: # | R14: #
A15: 13 | B15: Loss of customer confidence | H15: # | I15: # | J15: # | K15: # | M15: # | P15: # | Q15: # | R15: # | S15: # | U15: #
A16: 14 | B16: loss of credibility in the internal information system | I16: # | K16: # | M16: # | P16: # | Q16: # | R16: # | S16: # | T16: #
A17: 15 | B17: Disruption of internal operation | C17: # | D17: # | E17: # | F17: # | G17: # | H17: # | I17: # | J17: # | K17: # | M17: # | N17: # | P17: #
A18: 16 | B18: disruption in the organization itself | C18: # | D18: # | E18: # | F18: # | G18: # | H18: # | I18: # | J18: # | K18: # | M18: # | P18: # | R18: #
A19: 17 | B19: additional internal cost | C19: # | D19: # | E19: # | F19: # | H19: # | J19: # | K19: # | N19: #
A20: 18 | B20: Disruption of a third party's operation: | C20: # | D20: # | E20: # | F20: # | G20: # | H20: # | I20: # | J20: # | K20: # | P20: # | U20: #
A21: 19 | B21: disruption in third parties transacting with the organization | C21: # | D21: # | E21: # | F21: # | G21: # | H21: # | I21: # | J21: # | K21: #
A22: 20 | B22: various types of injury | C22: # | D22: # | E22: # | F22: # | L22: # | P22: #
A23: 21 | B23: inability to fulfill legal obligations | K23: # | R23: # | U23: #
A24: 22 | B24: Breach of contract: | I24: # | J24: # | K24: # | Q24: # | R24: # | U24: #
A25: 23 | B25: inability to fulfill contractual obligations | C25: # | D25: # | E25: # | F25: # | I25: # | J25: # | P25: # | Q25: # | R25: # | U25: #
A26: 24 | B26: Danger to personnel / user safety: | C26: # | D26: # | E26: # | F26: # | G26: # | H26: # | L26: # | M26: # | O26: # | P26: #
A27: 25 | B27: danger for the organization's personnel and / or users | C27: # | D27: # | E27: # | F27: # | G27: # | H27: # | L27: # | M27: # | O27: # | P27: # | T27: #
A28: 26 | B28: Loss of goods / funds / assets | C28: # | D28: # | E28: # | F28: # | H28: # | K28: # | N28: # | S28: # | T28: #
A29: 27 | B29: Loss of customers, loss of suppliers | K29: # | P29: # | Q29: # | R29: # | S29: # | U29: #
A30: 28 | B30: Judicial proceedings and penalties | K30: # | O30: # | P30: # | Q30: # | R30: # | S30: # | T30: #
A31: 29 | B31: Loss of a competitive advantage | C31: # | D31: # | E31: # | F31: # | I31: # | K31: # | N31: # | O31: # | P31: # | Q31: # | R31: # | S31: #
A32: 30 | B32: Industrial crisis (strikes) | P32: # | T32: #
A33: 31 | B33: Government crisis | P33: #
A34: 32 | B34: Dismissal | N34: # | O34: # | S34: # | T34: # | U34: #
A35: 33 | B35: Material damage | C35: # | D35: # | E35: # | F35: # | J35: # | M35: # | O35: # | P35: #
A55: Public Utilities Failure (Power/Water) | B55: Impairment of business performance | C55: Loss of goodwill/negative effect on reputation | D55: Endangerment of personal safety | E55: Financial loss | F55: Disruption to business activities | G55: Interruption of service | H55: Disruption of internal operation | I55: disruption in the organization itself | J55: inability to provide the service | K55: additional internal cost | L55: Loss of customer confidence | M55: Disruption of a third party's operation: | N55: Danger to personnel / user safety: | O55: inability to fulfill contractual obligations | P55: disruption in third parties transacting with the organization | Q55: various types of injury
